2021-12-14 19:11:23,533 INFO    MainThread:13413 [internal.py:wandb_internal():91] W&B internal server running at pid: 13413, started at: 2021-12-14 19:11:23.533605
2021-12-14 19:11:23,537 INFO    WriterThread:13413 [datastore.py:open_for_write():80] open: output/wandb/offline-run-20211214_191122-10m2m4p7/run-10m2m4p7.wandb
2021-12-14 19:11:23,540 DEBUG   HandlerThread:13413 [handler.py:handle_request():124] handle_request: run_start
2021-12-14 19:11:25,066 DEBUG   HandlerThread:13413 [meta.py:__init__():39] meta init
2021-12-14 19:11:25,066 DEBUG   HandlerThread:13413 [meta.py:__init__():53] meta init done
2021-12-14 19:11:25,067 DEBUG   HandlerThread:13413 [meta.py:probe():210] probe
2021-12-14 19:11:25,073 DEBUG   HandlerThread:13413 [meta.py:_setup_git():200] setup git
2021-12-14 19:11:25,099 DEBUG   HandlerThread:13413 [meta.py:_setup_git():207] setup git done
2021-12-14 19:11:25,099 DEBUG   HandlerThread:13413 [meta.py:_save_pip():57] save pip
2021-12-14 19:11:25,100 DEBUG   HandlerThread:13413 [meta.py:_save_pip():71] save pip done
2021-12-14 19:11:25,100 DEBUG   HandlerThread:13413 [meta.py:_save_conda():78] save conda
2021-12-14 19:11:28,414 DEBUG   HandlerThread:13413 [meta.py:_save_conda():86] save conda done
2021-12-14 19:11:28,414 DEBUG   HandlerThread:13413 [meta.py:probe():252] probe done
2021-12-14 19:11:52,740 WARNING MainThread:13413 [internal.py:wandb_internal():147] Internal process interrupt: 1
2021-12-14 19:11:52,918 WARNING MainThread:13413 [internal.py:wandb_internal():147] Internal process interrupt: 2
2021-12-14 19:11:52,918 ERROR   MainThread:13413 [internal.py:wandb_internal():150] Internal process interrupted.
2021-12-14 19:11:53,425 INFO    WriterThread:13413 [datastore.py:close():288] close: output/wandb/offline-run-20211214_191122-10m2m4p7/run-10m2m4p7.wandb
2021-12-14 19:11:53,448 INFO    HandlerThread:13413 [handler.py:finish():658] shutting down handler
2021-12-14 19:11:53,548 INFO    SenderThread:13413 [sender.py:finish():947] shutting down sender
2021-12-14 19:11:53,549 INFO    MainThread:13413 [internal.py:handle_exit():78] Internal process exited
