2021-12-14 17:45:04,935 INFO    MainThread:6563 [internal.py:wandb_internal():91] W&B internal server running at pid: 6563, started at: 2021-12-14 17:45:04.935635
2021-12-14 17:45:04,939 INFO    WriterThread:6563 [datastore.py:open_for_write():80] open: output/wandb/offline-run-20211214_174504-25xzv1d9/run-25xzv1d9.wandb
2021-12-14 17:45:04,941 DEBUG   HandlerThread:6563 [handler.py:handle_request():124] handle_request: run_start
2021-12-14 17:45:06,511 DEBUG   HandlerThread:6563 [meta.py:__init__():39] meta init
2021-12-14 17:45:06,511 DEBUG   HandlerThread:6563 [meta.py:__init__():53] meta init done
2021-12-14 17:45:06,511 DEBUG   HandlerThread:6563 [meta.py:probe():210] probe
2021-12-14 17:45:06,518 DEBUG   HandlerThread:6563 [meta.py:_setup_git():200] setup git
2021-12-14 17:45:06,545 DEBUG   HandlerThread:6563 [meta.py:_setup_git():207] setup git done
2021-12-14 17:45:06,545 DEBUG   HandlerThread:6563 [meta.py:_save_pip():57] save pip
2021-12-14 17:45:06,546 DEBUG   HandlerThread:6563 [meta.py:_save_pip():71] save pip done
2021-12-14 17:45:06,546 DEBUG   HandlerThread:6563 [meta.py:_save_conda():78] save conda
2021-12-14 17:45:09,551 DEBUG   HandlerThread:6563 [meta.py:_save_conda():86] save conda done
2021-12-14 17:45:09,551 DEBUG   HandlerThread:6563 [meta.py:probe():252] probe done
2021-12-14 17:47:31,129 WARNING MainThread:6563 [internal.py:wandb_internal():147] Internal process interrupt: 1
2021-12-14 17:47:31,308 WARNING MainThread:6563 [internal.py:wandb_internal():147] Internal process interrupt: 2
2021-12-14 17:47:31,308 ERROR   MainThread:6563 [internal.py:wandb_internal():150] Internal process interrupted.
2021-12-14 17:47:31,971 INFO    SenderThread:6563 [sender.py:finish():947] shutting down sender
2021-12-14 17:47:32,153 INFO    WriterThread:6563 [datastore.py:close():288] close: output/wandb/offline-run-20211214_174504-25xzv1d9/run-25xzv1d9.wandb
2021-12-14 17:47:32,174 INFO    HandlerThread:6563 [handler.py:finish():658] shutting down handler
2021-12-14 17:47:32,176 INFO    MainThread:6563 [internal.py:handle_exit():78] Internal process exited
