2022-02-07 15:15:50,216 INFO    MainThread:14197 [internal.py:wandb_internal():91] W&B internal server running at pid: 14197, started at: 2022-02-07 15:15:50.216144
2022-02-07 15:15:50,220 INFO    WriterThread:14197 [datastore.py:open_for_write():80] open: output/wandb/offline-run-20220207_151549-zbvht8x8/run-zbvht8x8.wandb
2022-02-07 15:15:50,222 DEBUG   HandlerThread:14197 [handler.py:handle_request():124] handle_request: run_start
2022-02-07 15:15:51,730 DEBUG   HandlerThread:14197 [meta.py:__init__():39] meta init
2022-02-07 15:15:51,730 DEBUG   HandlerThread:14197 [meta.py:__init__():53] meta init done
2022-02-07 15:15:51,730 DEBUG   HandlerThread:14197 [meta.py:probe():210] probe
2022-02-07 15:15:51,737 DEBUG   HandlerThread:14197 [meta.py:_setup_git():200] setup git
2022-02-07 15:15:51,762 DEBUG   HandlerThread:14197 [meta.py:_setup_git():207] setup git done
2022-02-07 15:15:51,762 DEBUG   HandlerThread:14197 [meta.py:_save_pip():57] save pip
2022-02-07 15:15:51,763 DEBUG   HandlerThread:14197 [meta.py:_save_pip():71] save pip done
2022-02-07 15:15:51,763 DEBUG   HandlerThread:14197 [meta.py:_save_conda():78] save conda
2022-02-07 15:15:54,818 DEBUG   HandlerThread:14197 [meta.py:_save_conda():86] save conda done
2022-02-07 15:15:54,818 DEBUG   HandlerThread:14197 [meta.py:probe():252] probe done
2022-02-07 15:16:16,261 WARNING MainThread:14197 [internal.py:wandb_internal():147] Internal process interrupt: 1
2022-02-07 15:16:16,427 WARNING MainThread:14197 [internal.py:wandb_internal():147] Internal process interrupt: 2
2022-02-07 15:16:16,427 ERROR   MainThread:14197 [internal.py:wandb_internal():150] Internal process interrupted.
2022-02-07 15:16:16,827 INFO    WriterThread:14197 [datastore.py:close():288] close: output/wandb/offline-run-20220207_151549-zbvht8x8/run-zbvht8x8.wandb
2022-02-07 15:16:16,849 INFO    HandlerThread:14197 [handler.py:finish():658] shutting down handler
2022-02-07 15:16:17,229 INFO    SenderThread:14197 [sender.py:finish():947] shutting down sender
2022-02-07 15:16:17,230 INFO    MainThread:14197 [internal.py:handle_exit():78] Internal process exited
