2022-02-15 16:47:01,351 INFO    MainThread:18933 [internal.py:wandb_internal():91] W&B internal server running at pid: 18933, started at: 2022-02-15 16:47:01.351500
2022-02-15 16:47:01,355 DEBUG   HandlerThread:18933 [handler.py:handle_request():124] handle_request: run_start
2022-02-15 16:47:01,356 INFO    WriterThread:18933 [datastore.py:open_for_write():80] open: output/wandb/offline-run-20220215_164700-3ht163ap/run-3ht163ap.wandb
2022-02-15 16:47:02,896 DEBUG   HandlerThread:18933 [meta.py:__init__():39] meta init
2022-02-15 16:47:02,896 DEBUG   HandlerThread:18933 [meta.py:__init__():53] meta init done
2022-02-15 16:47:02,896 DEBUG   HandlerThread:18933 [meta.py:probe():210] probe
2022-02-15 16:47:02,902 DEBUG   HandlerThread:18933 [meta.py:_setup_git():200] setup git
2022-02-15 16:47:02,929 DEBUG   HandlerThread:18933 [meta.py:_setup_git():207] setup git done
2022-02-15 16:47:02,929 DEBUG   HandlerThread:18933 [meta.py:_save_pip():57] save pip
2022-02-15 16:47:02,930 DEBUG   HandlerThread:18933 [meta.py:_save_pip():71] save pip done
2022-02-15 16:47:02,930 DEBUG   HandlerThread:18933 [meta.py:_save_conda():78] save conda
2022-02-15 16:47:06,054 DEBUG   HandlerThread:18933 [meta.py:_save_conda():86] save conda done
2022-02-15 16:47:06,054 DEBUG   HandlerThread:18933 [meta.py:probe():252] probe done
2022-02-15 16:47:08,134 WARNING MainThread:18933 [internal.py:wandb_internal():147] Internal process interrupt: 1
2022-02-15 16:47:08,305 WARNING MainThread:18933 [internal.py:wandb_internal():147] Internal process interrupt: 2
2022-02-15 16:47:08,305 ERROR   MainThread:18933 [internal.py:wandb_internal():150] Internal process interrupted.
2022-02-15 16:47:08,364 INFO    SenderThread:18933 [sender.py:finish():947] shutting down sender
2022-02-15 16:47:09,058 INFO    WriterThread:18933 [datastore.py:close():288] close: output/wandb/offline-run-20220215_164700-3ht163ap/run-3ht163ap.wandb
2022-02-15 16:47:09,061 INFO    HandlerThread:18933 [handler.py:finish():658] shutting down handler
2022-02-15 16:47:09,062 INFO    MainThread:18933 [internal.py:handle_exit():78] Internal process exited
