2022-02-07 15:16:48,286 INFO    MainThread:14579 [internal.py:wandb_internal():91] W&B internal server running at pid: 14579, started at: 2022-02-07 15:16:48.286561
2022-02-07 15:16:48,290 INFO    WriterThread:14579 [datastore.py:open_for_write():80] open: output/wandb/offline-run-20220207_151647-29e15989/run-29e15989.wandb
2022-02-07 15:16:48,292 DEBUG   HandlerThread:14579 [handler.py:handle_request():124] handle_request: run_start
2022-02-07 15:16:49,812 DEBUG   HandlerThread:14579 [meta.py:__init__():39] meta init
2022-02-07 15:16:49,812 DEBUG   HandlerThread:14579 [meta.py:__init__():53] meta init done
2022-02-07 15:16:49,812 DEBUG   HandlerThread:14579 [meta.py:probe():210] probe
2022-02-07 15:16:49,819 DEBUG   HandlerThread:14579 [meta.py:_setup_git():200] setup git
2022-02-07 15:16:49,846 DEBUG   HandlerThread:14579 [meta.py:_setup_git():207] setup git done
2022-02-07 15:16:49,846 DEBUG   HandlerThread:14579 [meta.py:_save_pip():57] save pip
2022-02-07 15:16:49,847 DEBUG   HandlerThread:14579 [meta.py:_save_pip():71] save pip done
2022-02-07 15:16:49,847 DEBUG   HandlerThread:14579 [meta.py:_save_conda():78] save conda
2022-02-07 15:16:52,867 DEBUG   HandlerThread:14579 [meta.py:_save_conda():86] save conda done
2022-02-07 15:16:52,867 DEBUG   HandlerThread:14579 [meta.py:probe():252] probe done
2022-02-07 15:18:30,556 WARNING MainThread:14579 [internal.py:wandb_internal():147] Internal process interrupt: 1
2022-02-07 15:18:30,751 WARNING MainThread:14579 [internal.py:wandb_internal():147] Internal process interrupt: 2
2022-02-07 15:18:30,752 ERROR   MainThread:14579 [internal.py:wandb_internal():150] Internal process interrupted.
2022-02-07 15:18:31,068 INFO    WriterThread:14579 [datastore.py:close():288] close: output/wandb/offline-run-20220207_151647-29e15989/run-29e15989.wandb
2022-02-07 15:18:31,080 INFO    HandlerThread:14579 [handler.py:finish():658] shutting down handler
2022-02-07 15:18:31,313 INFO    SenderThread:14579 [sender.py:finish():947] shutting down sender
2022-02-07 15:18:31,314 INFO    MainThread:14579 [internal.py:handle_exit():78] Internal process exited
