2022-02-04 13:49:41,819 INFO    MainThread:14347 [internal.py:wandb_internal():91] W&B internal server running at pid: 14347, started at: 2022-02-04 13:49:41.819226
2022-02-04 13:49:41,823 INFO    WriterThread:14347 [datastore.py:open_for_write():80] open: output/wandb/offline-run-20220204_134940-2mtg5vqv/run-2mtg5vqv.wandb
2022-02-04 13:49:41,825 DEBUG   HandlerThread:14347 [handler.py:handle_request():124] handle_request: run_start
2022-02-04 13:49:43,471 DEBUG   HandlerThread:14347 [meta.py:__init__():39] meta init
2022-02-04 13:49:43,471 DEBUG   HandlerThread:14347 [meta.py:__init__():53] meta init done
2022-02-04 13:49:43,471 DEBUG   HandlerThread:14347 [meta.py:probe():210] probe
2022-02-04 13:49:43,478 DEBUG   HandlerThread:14347 [meta.py:_setup_git():200] setup git
2022-02-04 13:49:43,506 DEBUG   HandlerThread:14347 [meta.py:_setup_git():207] setup git done
2022-02-04 13:49:43,506 DEBUG   HandlerThread:14347 [meta.py:_save_pip():57] save pip
2022-02-04 13:49:43,507 DEBUG   HandlerThread:14347 [meta.py:_save_pip():71] save pip done
2022-02-04 13:49:43,507 DEBUG   HandlerThread:14347 [meta.py:_save_conda():78] save conda
2022-02-04 13:49:46,556 DEBUG   HandlerThread:14347 [meta.py:_save_conda():86] save conda done
2022-02-04 13:49:46,557 DEBUG   HandlerThread:14347 [meta.py:probe():252] probe done
2022-02-04 13:49:58,494 WARNING MainThread:14347 [internal.py:wandb_internal():147] Internal process interrupt: 1
2022-02-04 13:49:58,659 WARNING MainThread:14347 [internal.py:wandb_internal():147] Internal process interrupt: 2
2022-02-04 13:49:58,659 ERROR   MainThread:14347 [internal.py:wandb_internal():150] Internal process interrupted.
2022-02-04 13:49:58,830 INFO    SenderThread:14347 [sender.py:finish():947] shutting down sender
2022-02-04 13:49:59,565 INFO    WriterThread:14347 [datastore.py:close():288] close: output/wandb/offline-run-20220204_134940-2mtg5vqv/run-2mtg5vqv.wandb
2022-02-04 13:49:59,575 INFO    HandlerThread:14347 [handler.py:finish():658] shutting down handler
2022-02-04 13:49:59,576 INFO    MainThread:14347 [internal.py:handle_exit():78] Internal process exited
