2022-02-04 16:28:19,506 INFO    MainThread:21824 [internal.py:wandb_internal():91] W&B internal server running at pid: 21824, started at: 2022-02-04 16:28:19.505884
2022-02-04 16:28:19,509 INFO    WriterThread:21824 [datastore.py:open_for_write():80] open: output/wandb/offline-run-20220204_162818-1x55ntiw/run-1x55ntiw.wandb
2022-02-04 16:28:19,512 DEBUG   HandlerThread:21824 [handler.py:handle_request():124] handle_request: run_start
2022-02-04 16:28:21,146 DEBUG   HandlerThread:21824 [meta.py:__init__():39] meta init
2022-02-04 16:28:21,146 DEBUG   HandlerThread:21824 [meta.py:__init__():53] meta init done
2022-02-04 16:28:21,146 DEBUG   HandlerThread:21824 [meta.py:probe():210] probe
2022-02-04 16:28:21,153 DEBUG   HandlerThread:21824 [meta.py:_setup_git():200] setup git
2022-02-04 16:28:21,179 DEBUG   HandlerThread:21824 [meta.py:_setup_git():207] setup git done
2022-02-04 16:28:21,179 DEBUG   HandlerThread:21824 [meta.py:_save_pip():57] save pip
2022-02-04 16:28:21,180 DEBUG   HandlerThread:21824 [meta.py:_save_pip():71] save pip done
2022-02-04 16:28:21,180 DEBUG   HandlerThread:21824 [meta.py:_save_conda():78] save conda
2022-02-04 16:28:24,214 DEBUG   HandlerThread:21824 [meta.py:_save_conda():86] save conda done
2022-02-04 16:28:24,214 DEBUG   HandlerThread:21824 [meta.py:probe():252] probe done
2022-02-04 16:29:21,516 WARNING MainThread:21824 [internal.py:wandb_internal():147] Internal process interrupt: 1
2022-02-04 16:29:21,693 WARNING MainThread:21824 [internal.py:wandb_internal():147] Internal process interrupt: 2
2022-02-04 16:29:21,694 ERROR   MainThread:21824 [internal.py:wandb_internal():150] Internal process interrupted.
2022-02-04 16:29:22,076 INFO    WriterThread:21824 [datastore.py:close():288] close: output/wandb/offline-run-20220204_162818-1x55ntiw/run-1x55ntiw.wandb
2022-02-04 16:29:22,076 INFO    HandlerThread:21824 [handler.py:finish():658] shutting down handler
2022-02-04 16:29:22,525 INFO    SenderThread:21824 [sender.py:finish():947] shutting down sender
2022-02-04 16:29:22,526 INFO    MainThread:21824 [internal.py:handle_exit():78] Internal process exited
