2022-01-05 15:09:31,939 INFO    MainThread:20851 [internal.py:wandb_internal():91] W&B internal server running at pid: 20851, started at: 2022-01-05 15:09:31.939693
2022-01-05 15:09:31,943 INFO    WriterThread:20851 [datastore.py:open_for_write():80] open: output/wandb/offline-run-20220105_150931-3do125hp/run-3do125hp.wandb
2022-01-05 15:09:31,945 DEBUG   HandlerThread:20851 [handler.py:handle_request():124] handle_request: run_start
2022-01-05 15:09:33,512 DEBUG   HandlerThread:20851 [meta.py:__init__():39] meta init
2022-01-05 15:09:33,512 DEBUG   HandlerThread:20851 [meta.py:__init__():53] meta init done
2022-01-05 15:09:33,512 DEBUG   HandlerThread:20851 [meta.py:probe():210] probe
2022-01-05 15:09:33,518 DEBUG   HandlerThread:20851 [meta.py:_setup_git():200] setup git
2022-01-05 15:09:33,546 DEBUG   HandlerThread:20851 [meta.py:_setup_git():207] setup git done
2022-01-05 15:09:33,546 DEBUG   HandlerThread:20851 [meta.py:_save_pip():57] save pip
2022-01-05 15:09:33,547 DEBUG   HandlerThread:20851 [meta.py:_save_pip():71] save pip done
2022-01-05 15:09:33,547 DEBUG   HandlerThread:20851 [meta.py:_save_conda():78] save conda
2022-01-05 15:09:36,795 DEBUG   HandlerThread:20851 [meta.py:_save_conda():86] save conda done
2022-01-05 15:09:36,795 DEBUG   HandlerThread:20851 [meta.py:probe():252] probe done
2022-01-05 15:12:56,761 WARNING MainThread:20851 [internal.py:wandb_internal():147] Internal process interrupt: 1
2022-01-05 15:12:56,957 WARNING MainThread:20851 [internal.py:wandb_internal():147] Internal process interrupt: 2
2022-01-05 15:12:56,957 ERROR   MainThread:20851 [internal.py:wandb_internal():150] Internal process interrupted.
2022-01-05 15:12:56,985 INFO    SenderThread:20851 [sender.py:finish():947] shutting down sender
2022-01-05 15:12:57,128 INFO    WriterThread:20851 [datastore.py:close():288] close: output/wandb/offline-run-20220105_150931-3do125hp/run-3do125hp.wandb
2022-01-05 15:12:57,150 INFO    HandlerThread:20851 [handler.py:finish():658] shutting down handler
2022-01-05 15:12:57,151 INFO    MainThread:20851 [internal.py:handle_exit():78] Internal process exited
