2022-02-13 02:02:22,211 INFO    MainThread:4491 [internal.py:wandb_internal():91] W&B internal server running at pid: 4491, started at: 2022-02-13 02:02:22.210880
2022-02-13 02:02:22,214 INFO    WriterThread:4491 [datastore.py:open_for_write():80] open: output/wandb/offline-run-20220213_020221-2b631z6l/run-2b631z6l.wandb
2022-02-13 02:02:22,217 DEBUG   HandlerThread:4491 [handler.py:handle_request():124] handle_request: run_start
2022-02-13 02:02:23,742 DEBUG   HandlerThread:4491 [meta.py:__init__():39] meta init
2022-02-13 02:02:23,742 DEBUG   HandlerThread:4491 [meta.py:__init__():53] meta init done
2022-02-13 02:02:23,742 DEBUG   HandlerThread:4491 [meta.py:probe():210] probe
2022-02-13 02:02:23,749 DEBUG   HandlerThread:4491 [meta.py:_setup_git():200] setup git
2022-02-13 02:02:23,775 DEBUG   HandlerThread:4491 [meta.py:_setup_git():207] setup git done
2022-02-13 02:02:23,775 DEBUG   HandlerThread:4491 [meta.py:_save_pip():57] save pip
2022-02-13 02:02:23,776 DEBUG   HandlerThread:4491 [meta.py:_save_pip():71] save pip done
2022-02-13 02:02:23,776 DEBUG   HandlerThread:4491 [meta.py:_save_conda():78] save conda
2022-02-13 02:02:26,999 DEBUG   HandlerThread:4491 [meta.py:_save_conda():86] save conda done
2022-02-13 02:02:26,999 DEBUG   HandlerThread:4491 [meta.py:probe():252] probe done
2022-02-13 02:04:22,260 WARNING MainThread:4491 [internal.py:wandb_internal():147] Internal process interrupt: 1
2022-02-13 02:04:22,428 WARNING MainThread:4491 [internal.py:wandb_internal():147] Internal process interrupt: 2
2022-02-13 02:04:22,428 ERROR   MainThread:4491 [internal.py:wandb_internal():150] Internal process interrupted.
2022-02-13 02:04:23,053 INFO    WriterThread:4491 [datastore.py:close():288] close: output/wandb/offline-run-20220213_020221-2b631z6l/run-2b631z6l.wandb
2022-02-13 02:04:23,080 INFO    HandlerThread:4491 [handler.py:finish():658] shutting down handler
2022-02-13 02:04:23,241 INFO    SenderThread:4491 [sender.py:finish():947] shutting down sender
2022-02-13 02:04:23,242 INFO    MainThread:4491 [internal.py:handle_exit():78] Internal process exited
