2022-01-05 13:57:26,621 INFO    MainThread:15214 [internal.py:wandb_internal():91] W&B internal server running at pid: 15214, started at: 2022-01-05 13:57:26.621277
2022-01-05 13:57:26,625 INFO    WriterThread:15214 [datastore.py:open_for_write():80] open: output/wandb/offline-run-20220105_135725-1pkyc22e/run-1pkyc22e.wandb
2022-01-05 13:57:26,629 DEBUG   HandlerThread:15214 [handler.py:handle_request():124] handle_request: run_start
2022-01-05 13:57:28,188 DEBUG   HandlerThread:15214 [meta.py:__init__():39] meta init
2022-01-05 13:57:28,188 DEBUG   HandlerThread:15214 [meta.py:__init__():53] meta init done
2022-01-05 13:57:28,188 DEBUG   HandlerThread:15214 [meta.py:probe():210] probe
2022-01-05 13:57:28,195 DEBUG   HandlerThread:15214 [meta.py:_setup_git():200] setup git
2022-01-05 13:57:28,222 DEBUG   HandlerThread:15214 [meta.py:_setup_git():207] setup git done
2022-01-05 13:57:28,222 DEBUG   HandlerThread:15214 [meta.py:_save_pip():57] save pip
2022-01-05 13:57:28,223 DEBUG   HandlerThread:15214 [meta.py:_save_pip():71] save pip done
2022-01-05 13:57:28,223 DEBUG   HandlerThread:15214 [meta.py:_save_conda():78] save conda
2022-01-05 13:57:30,935 WARNING MainThread:15214 [internal.py:wandb_internal():147] Internal process interrupt: 1
2022-01-05 13:57:31,059 DEBUG   HandlerThread:15214 [meta.py:_save_conda():86] save conda done
2022-01-05 13:57:31,060 DEBUG   HandlerThread:15214 [meta.py:probe():252] probe done
2022-01-05 13:57:31,122 WARNING MainThread:15214 [internal.py:wandb_internal():147] Internal process interrupt: 2
2022-01-05 13:57:31,123 ERROR   MainThread:15214 [internal.py:wandb_internal():150] Internal process interrupted.
2022-01-05 13:57:31,631 INFO    SenderThread:15214 [sender.py:finish():947] shutting down sender
2022-01-05 13:57:32,065 INFO    WriterThread:15214 [datastore.py:close():288] close: output/wandb/offline-run-20220105_135725-1pkyc22e/run-1pkyc22e.wandb
2022-01-05 13:57:32,065 INFO    HandlerThread:15214 [handler.py:finish():658] shutting down handler
2022-01-05 13:57:32,067 INFO    MainThread:15214 [internal.py:handle_exit():78] Internal process exited
