2022-01-06 17:01:17,459 INFO    MainThread:28317 [internal.py:wandb_internal():91] W&B internal server running at pid: 28317, started at: 2022-01-06 17:01:17.458788
2022-01-06 17:01:17,462 INFO    WriterThread:28317 [datastore.py:open_for_write():80] open: output/wandb/offline-run-20220106_170116-pbgvce79/run-pbgvce79.wandb
2022-01-06 17:01:17,465 DEBUG   HandlerThread:28317 [handler.py:handle_request():124] handle_request: run_start
2022-01-06 17:01:19,135 DEBUG   HandlerThread:28317 [meta.py:__init__():39] meta init
2022-01-06 17:01:19,135 DEBUG   HandlerThread:28317 [meta.py:__init__():53] meta init done
2022-01-06 17:01:19,135 DEBUG   HandlerThread:28317 [meta.py:probe():210] probe
2022-01-06 17:01:19,142 DEBUG   HandlerThread:28317 [meta.py:_setup_git():200] setup git
2022-01-06 17:01:19,177 DEBUG   HandlerThread:28317 [meta.py:_setup_git():207] setup git done
2022-01-06 17:01:19,178 DEBUG   HandlerThread:28317 [meta.py:_save_pip():57] save pip
2022-01-06 17:01:19,178 DEBUG   HandlerThread:28317 [meta.py:_save_pip():71] save pip done
2022-01-06 17:01:19,178 DEBUG   HandlerThread:28317 [meta.py:_save_conda():78] save conda
2022-01-06 17:01:22,330 DEBUG   HandlerThread:28317 [meta.py:_save_conda():86] save conda done
2022-01-06 17:01:22,331 DEBUG   HandlerThread:28317 [meta.py:probe():252] probe done
2022-01-06 17:01:35,254 WARNING MainThread:28317 [internal.py:wandb_internal():147] Internal process interrupt: 1
2022-01-06 17:01:35,454 WARNING MainThread:28317 [internal.py:wandb_internal():147] Internal process interrupt: 2
2022-01-06 17:01:35,454 ERROR   MainThread:28317 [internal.py:wandb_internal():150] Internal process interrupted.
2022-01-06 17:01:35,471 INFO    SenderThread:28317 [sender.py:finish():947] shutting down sender
2022-01-06 17:01:36,339 INFO    WriterThread:28317 [datastore.py:close():288] close: output/wandb/offline-run-20220106_170116-pbgvce79/run-pbgvce79.wandb
2022-01-06 17:01:36,351 INFO    HandlerThread:28317 [handler.py:finish():658] shutting down handler
2022-01-06 17:01:36,352 INFO    MainThread:28317 [internal.py:handle_exit():78] Internal process exited
