Train Mode
[32m2022-02-04 13:47:46.452[39m | [1mINFO[22m | [90m/home/avsp/Masa√ºst√º/GansNRoses/GansNRoses/environment/level_utils.py:76[39m | Tokens in level ['-', 'T', 'X']
  0%|                                                                                        | 0/15 [00:02<?, ?it/s]
Traceback (most recent call last):
  File "/home/avsp/anaconda3/envs/gpn/lib/python3.6/site-packages/PIL/ImageFile.py", line 496, in _save
    fh = fp.fileno()
AttributeError: '_idat' object has no attribute 'fileno'
During handling of the above exception, another exception occurred:
Traceback (most recent call last):
  File "main.py", line 91, in <module>
    main()
  File "main.py", line 71, in main
    generated_map = G.train(np.array(init_map), opt, i)
  File "/home/avsp/Masa√ºst√º/GansNRoses/GansNRoses/train.py", line 140, in train
    loss = test_score(idx)
  File "/home/avsp/Masa√ºst√º/GansNRoses/GansNRoses/train.py", line 41, in test_score
    obs, rewards, done, info = env.step(action)
  File "/home/avsp/Masa√ºst√º/GansNRoses/GansNRoses/environment/base_env.py", line 454, in step
    self.render()
  File "/home/avsp/Masa√ºst√º/GansNRoses/GansNRoses/environment/base_env.py", line 565, in render
    sprite_dict['T'].save(trap_path)
  File "/home/avsp/anaconda3/envs/gpn/lib/python3.6/site-packages/PIL/Image.py", line 2134, in save
    save_handler(self, fp, filename)
  File "/home/avsp/anaconda3/envs/gpn/lib/python3.6/site-packages/PIL/PngImagePlugin.py", line 1291, in _save
    ImageFile._save(im, _idat(fp, chunk), [("zip", (0, 0) + im.size, 0, rawmode)])
  File "/home/avsp/anaconda3/envs/gpn/lib/python3.6/site-packages/PIL/ImageFile.py", line 504, in _save
    e.setimage(im.im, b)
SystemError: tile cannot extend outside image