2022-02-12 19:50:46,391 INFO    MainThread:10469 [internal.py:wandb_internal():91] W&B internal server running at pid: 10469, started at: 2022-02-12 19:50:46.390813
2022-02-12 19:50:46,394 INFO    WriterThread:10469 [datastore.py:open_for_write():80] open: output/wandb/offline-run-20220212_195045-7x26gazo/run-7x26gazo.wandb
2022-02-12 19:50:46,397 DEBUG   HandlerThread:10469 [handler.py:handle_request():124] handle_request: run_start
2022-02-12 19:50:47,949 DEBUG   HandlerThread:10469 [meta.py:__init__():39] meta init
2022-02-12 19:50:47,949 DEBUG   HandlerThread:10469 [meta.py:__init__():53] meta init done
2022-02-12 19:50:47,949 DEBUG   HandlerThread:10469 [meta.py:probe():210] probe
2022-02-12 19:50:47,956 DEBUG   HandlerThread:10469 [meta.py:_setup_git():200] setup git
2022-02-12 19:50:47,985 DEBUG   HandlerThread:10469 [meta.py:_setup_git():207] setup git done
2022-02-12 19:50:47,986 DEBUG   HandlerThread:10469 [meta.py:_save_pip():57] save pip
2022-02-12 19:50:47,986 DEBUG   HandlerThread:10469 [meta.py:_save_pip():71] save pip done
2022-02-12 19:50:47,987 DEBUG   HandlerThread:10469 [meta.py:_save_conda():78] save conda
2022-02-12 19:50:51,108 DEBUG   HandlerThread:10469 [meta.py:_save_conda():86] save conda done
2022-02-12 19:50:51,108 DEBUG   HandlerThread:10469 [meta.py:probe():252] probe done
2022-02-12 19:50:59,235 WARNING MainThread:10469 [internal.py:wandb_internal():147] Internal process interrupt: 1
2022-02-12 19:50:59,418 WARNING MainThread:10469 [internal.py:wandb_internal():147] Internal process interrupt: 2
2022-02-12 19:50:59,418 ERROR   MainThread:10469 [internal.py:wandb_internal():150] Internal process interrupted.
2022-02-12 19:51:00,115 INFO    WriterThread:10469 [datastore.py:close():288] close: output/wandb/offline-run-20220212_195045-7x26gazo/run-7x26gazo.wandb
2022-02-12 19:51:00,123 INFO    HandlerThread:10469 [handler.py:finish():658] shutting down handler
2022-02-12 19:51:00,402 INFO    SenderThread:10469 [sender.py:finish():947] shutting down sender
2022-02-12 19:51:00,403 INFO    MainThread:10469 [internal.py:handle_exit():78] Internal process exited
