2022-02-13 19:57:10,538 INFO    MainThread:8089 [internal.py:wandb_internal():91] W&B internal server running at pid: 8089, started at: 2022-02-13 19:57:10.538248
2022-02-13 19:57:10,542 DEBUG   HandlerThread:8089 [handler.py:handle_request():124] handle_request: run_start
2022-02-13 19:57:10,544 INFO    WriterThread:8089 [datastore.py:open_for_write():80] open: output/wandb/offline-run-20220213_195709-1j4p1zk9/run-1j4p1zk9.wandb
2022-02-13 19:57:12,851 DEBUG   HandlerThread:8089 [meta.py:__init__():39] meta init
2022-02-13 19:57:12,851 DEBUG   HandlerThread:8089 [meta.py:__init__():53] meta init done
2022-02-13 19:57:12,851 DEBUG   HandlerThread:8089 [meta.py:probe():210] probe
2022-02-13 19:57:12,859 DEBUG   HandlerThread:8089 [meta.py:_setup_git():200] setup git
2022-02-13 19:57:12,889 DEBUG   HandlerThread:8089 [meta.py:_setup_git():207] setup git done
2022-02-13 19:57:12,889 DEBUG   HandlerThread:8089 [meta.py:_save_pip():57] save pip
2022-02-13 19:57:12,890 DEBUG   HandlerThread:8089 [meta.py:_save_pip():71] save pip done
2022-02-13 19:57:12,891 DEBUG   HandlerThread:8089 [meta.py:_save_conda():78] save conda
2022-02-13 19:57:16,506 DEBUG   HandlerThread:8089 [meta.py:_save_conda():86] save conda done
2022-02-13 19:57:16,506 DEBUG   HandlerThread:8089 [meta.py:probe():252] probe done
2022-02-13 19:57:32,942 WARNING MainThread:8089 [internal.py:wandb_internal():147] Internal process interrupt: 1
2022-02-13 19:57:33,180 WARNING MainThread:8089 [internal.py:wandb_internal():147] Internal process interrupt: 2
2022-02-13 19:57:33,180 ERROR   MainThread:8089 [internal.py:wandb_internal():150] Internal process interrupted.
2022-02-13 19:57:33,516 INFO    WriterThread:8089 [datastore.py:close():288] close: output/wandb/offline-run-20220213_195709-1j4p1zk9/run-1j4p1zk9.wandb
2022-02-13 19:57:33,531 INFO    HandlerThread:8089 [handler.py:finish():658] shutting down handler
2022-02-13 19:57:33,554 INFO    SenderThread:8089 [sender.py:finish():947] shutting down sender
2022-02-13 19:57:33,555 INFO    MainThread:8089 [internal.py:handle_exit():78] Internal process exited
