2022-02-13 19:59:09,652 INFO    MainThread:9041 [internal.py:wandb_internal():91] W&B internal server running at pid: 9041, started at: 2022-02-13 19:59:09.651861
2022-02-13 19:59:09,655 INFO    WriterThread:9041 [datastore.py:open_for_write():80] open: output/wandb/offline-run-20220213_195908-3fl1p15p/run-3fl1p15p.wandb
2022-02-13 19:59:09,658 DEBUG   HandlerThread:9041 [handler.py:handle_request():124] handle_request: run_start
2022-02-13 19:59:11,589 DEBUG   HandlerThread:9041 [meta.py:__init__():39] meta init
2022-02-13 19:59:11,589 DEBUG   HandlerThread:9041 [meta.py:__init__():53] meta init done
2022-02-13 19:59:11,589 DEBUG   HandlerThread:9041 [meta.py:probe():210] probe
2022-02-13 19:59:11,596 DEBUG   HandlerThread:9041 [meta.py:_setup_git():200] setup git
2022-02-13 19:59:11,626 DEBUG   HandlerThread:9041 [meta.py:_setup_git():207] setup git done
2022-02-13 19:59:11,627 DEBUG   HandlerThread:9041 [meta.py:_save_pip():57] save pip
2022-02-13 19:59:11,627 DEBUG   HandlerThread:9041 [meta.py:_save_pip():71] save pip done
2022-02-13 19:59:11,628 DEBUG   HandlerThread:9041 [meta.py:_save_conda():78] save conda
2022-02-13 19:59:15,214 DEBUG   HandlerThread:9041 [meta.py:_save_conda():86] save conda done
2022-02-13 19:59:15,214 DEBUG   HandlerThread:9041 [meta.py:probe():252] probe done
2022-02-13 20:00:24,152 WARNING MainThread:9041 [internal.py:wandb_internal():147] Internal process interrupt: 1
2022-02-13 20:00:24,373 WARNING MainThread:9041 [internal.py:wandb_internal():147] Internal process interrupt: 2
2022-02-13 20:00:24,373 ERROR   MainThread:9041 [internal.py:wandb_internal():150] Internal process interrupted.
2022-02-13 20:00:24,619 INFO    WriterThread:9041 [datastore.py:close():288] close: output/wandb/offline-run-20220213_195908-3fl1p15p/run-3fl1p15p.wandb
2022-02-13 20:00:24,631 INFO    HandlerThread:9041 [handler.py:finish():658] shutting down handler
2022-02-13 20:00:24,675 INFO    SenderThread:9041 [sender.py:finish():947] shutting down sender
2022-02-13 20:00:24,675 INFO    MainThread:9041 [internal.py:handle_exit():78] Internal process exited
