2022-02-03 23:46:35,349 INFO    MainThread:11929 [internal.py:wandb_internal():91] W&B internal server running at pid: 11929, started at: 2022-02-03 23:46:35.349581
2022-02-03 23:46:35,352 INFO    WriterThread:11929 [datastore.py:open_for_write():80] open: output/wandb/offline-run-20220203_234634-50yh6scv/run-50yh6scv.wandb
2022-02-03 23:46:35,356 DEBUG   HandlerThread:11929 [handler.py:handle_request():124] handle_request: run_start
2022-02-03 23:46:36,869 DEBUG   HandlerThread:11929 [meta.py:__init__():39] meta init
2022-02-03 23:46:36,869 DEBUG   HandlerThread:11929 [meta.py:__init__():53] meta init done
2022-02-03 23:46:36,869 DEBUG   HandlerThread:11929 [meta.py:probe():210] probe
2022-02-03 23:46:36,876 DEBUG   HandlerThread:11929 [meta.py:_setup_git():200] setup git
2022-02-03 23:46:36,902 DEBUG   HandlerThread:11929 [meta.py:_setup_git():207] setup git done
2022-02-03 23:46:36,902 DEBUG   HandlerThread:11929 [meta.py:_save_pip():57] save pip
2022-02-03 23:46:36,903 DEBUG   HandlerThread:11929 [meta.py:_save_pip():71] save pip done
2022-02-03 23:46:36,903 DEBUG   HandlerThread:11929 [meta.py:_save_conda():78] save conda
2022-02-03 23:46:40,003 DEBUG   HandlerThread:11929 [meta.py:_save_conda():86] save conda done
2022-02-03 23:46:40,004 DEBUG   HandlerThread:11929 [meta.py:probe():252] probe done
2022-02-03 23:46:51,329 WARNING MainThread:11929 [internal.py:wandb_internal():147] Internal process interrupt: 1
2022-02-03 23:46:51,505 WARNING MainThread:11929 [internal.py:wandb_internal():147] Internal process interrupt: 2
2022-02-03 23:46:51,505 ERROR   MainThread:11929 [internal.py:wandb_internal():150] Internal process interrupted.
2022-02-03 23:46:52,011 INFO    WriterThread:11929 [datastore.py:close():288] close: output/wandb/offline-run-20220203_234634-50yh6scv/run-50yh6scv.wandb
2022-02-03 23:46:52,022 INFO    HandlerThread:11929 [handler.py:finish():658] shutting down handler
2022-02-03 23:46:52,361 INFO    SenderThread:11929 [sender.py:finish():947] shutting down sender
2022-02-03 23:46:52,362 INFO    MainThread:11929 [internal.py:handle_exit():78] Internal process exited
