2022-02-03 23:45:29,264 INFO    MainThread:11658 [internal.py:wandb_internal():91] W&B internal server running at pid: 11658, started at: 2022-02-03 23:45:29.264548
2022-02-03 23:45:29,268 INFO    WriterThread:11658 [datastore.py:open_for_write():80] open: output/wandb/offline-run-20220203_234528-2rst16xc/run-2rst16xc.wandb
2022-02-03 23:45:29,270 DEBUG   HandlerThread:11658 [handler.py:handle_request():124] handle_request: run_start
2022-02-03 23:45:30,752 DEBUG   HandlerThread:11658 [meta.py:__init__():39] meta init
2022-02-03 23:45:30,752 DEBUG   HandlerThread:11658 [meta.py:__init__():53] meta init done
2022-02-03 23:45:30,752 DEBUG   HandlerThread:11658 [meta.py:probe():210] probe
2022-02-03 23:45:30,758 DEBUG   HandlerThread:11658 [meta.py:_setup_git():200] setup git
2022-02-03 23:45:30,783 DEBUG   HandlerThread:11658 [meta.py:_setup_git():207] setup git done
2022-02-03 23:45:30,784 DEBUG   HandlerThread:11658 [meta.py:_save_pip():57] save pip
2022-02-03 23:45:30,784 DEBUG   HandlerThread:11658 [meta.py:_save_pip():71] save pip done
2022-02-03 23:45:30,785 DEBUG   HandlerThread:11658 [meta.py:_save_conda():78] save conda
2022-02-03 23:45:34,056 DEBUG   HandlerThread:11658 [meta.py:_save_conda():86] save conda done
2022-02-03 23:45:34,057 DEBUG   HandlerThread:11658 [meta.py:probe():252] probe done
2022-02-03 23:45:50,642 WARNING MainThread:11658 [internal.py:wandb_internal():147] Internal process interrupt: 1
2022-02-03 23:45:50,842 WARNING MainThread:11658 [internal.py:wandb_internal():147] Internal process interrupt: 2
2022-02-03 23:45:50,842 ERROR   MainThread:11658 [internal.py:wandb_internal():150] Internal process interrupted.
2022-02-03 23:45:51,065 INFO    WriterThread:11658 [datastore.py:close():288] close: output/wandb/offline-run-20220203_234528-2rst16xc/run-2rst16xc.wandb
2022-02-03 23:45:51,080 INFO    HandlerThread:11658 [handler.py:finish():658] shutting down handler
2022-02-03 23:45:51,276 INFO    SenderThread:11658 [sender.py:finish():947] shutting down sender
2022-02-03 23:45:51,277 INFO    MainThread:11658 [internal.py:handle_exit():78] Internal process exited
