2022-02-04 17:03:40,751 INFO    MainThread:23923 [internal.py:wandb_internal():91] W&B internal server running at pid: 23923, started at: 2022-02-04 17:03:40.751073
2022-02-04 17:03:40,754 INFO    WriterThread:23923 [datastore.py:open_for_write():80] open: output/wandb/offline-run-20220204_170339-2hb59qgd/run-2hb59qgd.wandb
2022-02-04 17:03:40,757 DEBUG   HandlerThread:23923 [handler.py:handle_request():124] handle_request: run_start
2022-02-04 17:03:42,386 DEBUG   HandlerThread:23923 [meta.py:__init__():39] meta init
2022-02-04 17:03:42,386 DEBUG   HandlerThread:23923 [meta.py:__init__():53] meta init done
2022-02-04 17:03:42,386 DEBUG   HandlerThread:23923 [meta.py:probe():210] probe
2022-02-04 17:03:42,393 DEBUG   HandlerThread:23923 [meta.py:_setup_git():200] setup git
2022-02-04 17:03:42,420 DEBUG   HandlerThread:23923 [meta.py:_setup_git():207] setup git done
2022-02-04 17:03:42,420 DEBUG   HandlerThread:23923 [meta.py:_save_pip():57] save pip
2022-02-04 17:03:42,421 DEBUG   HandlerThread:23923 [meta.py:_save_pip():71] save pip done
2022-02-04 17:03:42,421 DEBUG   HandlerThread:23923 [meta.py:_save_conda():78] save conda
2022-02-04 17:03:45,538 DEBUG   HandlerThread:23923 [meta.py:_save_conda():86] save conda done
2022-02-04 17:03:45,539 DEBUG   HandlerThread:23923 [meta.py:probe():252] probe done
2022-02-04 17:04:56,838 WARNING MainThread:23923 [internal.py:wandb_internal():147] Internal process interrupt: 1
2022-02-04 17:04:57,005 WARNING MainThread:23923 [internal.py:wandb_internal():147] Internal process interrupt: 2
2022-02-04 17:04:57,005 ERROR   MainThread:23923 [internal.py:wandb_internal():150] Internal process interrupted.
2022-02-04 17:04:57,280 INFO    WriterThread:23923 [datastore.py:close():288] close: output/wandb/offline-run-20220204_170339-2hb59qgd/run-2hb59qgd.wandb
2022-02-04 17:04:57,293 INFO    HandlerThread:23923 [handler.py:finish():658] shutting down handler
2022-02-04 17:04:57,774 INFO    SenderThread:23923 [sender.py:finish():947] shutting down sender
2022-02-04 17:04:57,776 INFO    MainThread:23923 [internal.py:handle_exit():78] Internal process exited
